Workbook
Name InfIndividual: NOTAS!$GD$118
Name informeAnual: NOTAS!$DN$6
Name INFORMEMEJORAMIENTO: NOTAS!$EF$4
Name INFORMESUPLETORIO: NOTAS!$EZ$4
Name primerPprimerQ: NOTAS!$D$6
Name primerQ: NOTAS!$CI$6
Name segundoPprimerQ: NOTAS!$AC$6
Name tercerPprimerQ: NOTAS!$BH$6
Name UNIDAD_EDUCATIVA: NOTAS!$D$4

Sheet TRI-1
B1: UNIDAD EDUCATIVA " "
B3: INFORME DEL PRIMER TRIMESTRE DE APRENDIZAJE
FC4: S
FC5: F
B6: 1 | C6: GRADO O CURSO: | D6: =NOTAS!B14 -> INICIAL II | O6: 3 | P6: AÑO LECTIVO: | Q6: =NOTAS!B18 -> 2025-2026 MATUTINA | FC6: O
B7: 2 | C7: DOCENTE: | D7: =NOTAS!B24 -> CUZCO GUERRERO JENNY DEL PILAR | O7: 4 | P7: FECHA: | Q7: =TODAY() -> 45994 | FC7: N
B10: Nº | C10: NÓMINA | G10: IDENTIDAD Y AUTONOMÍA | Z10: CONVIVENCIA | AP10: RELACIONES CON EL MEDIO NATURAL Y CULTURAL | BK10: RELACIONES LOGICAS MATEMATICAS | CH10: COMPRENSIÓN Y EXPRESION DEL LENGUAJE | DD10: EXPRESIÓN ARTISTICA | DP10: EXPRESION CORPORAL Y MOTRICIDAD | ES10: PROMEDIO GENERAL | ET10: CÍVICA Y ACOMPAÑAMIENTO INTEGRAL EN EL AULA | FC10: PROMEDIO FINAL CIVICA Y ACOMPAÑMIENTO INTEGRAL EN EL AULA | FE10: I TRIMESTRE
Y11: PROMEDIO | AO11: PROMEDIO | BJ11: PROMEDIO | CG11: PROMEDIO | DC11: PROMEDIO
G13: Comunicar algunos datos de su identidad como: nombres completos, edad, nombres de familiares cercanos, lugar dónde vive. | H13: Demostrar curiosidad por las características físicas (genitales) que le permiten reconocerse como niño y niña | I13: Identificar la importancia de usar el cinturón de seguridad para promover el autocuidado y la protección personal. | J13: Identificar las situaciones de peligro a las que se puede exponer en su entorno inmediato y seguir pautas de comportamiento para evitarlas. | K13: Identificar sus características físicas y las de las personas de su entorno como parte del proceso de aceptación de sí mismo y de respeto a los demás. | L13: Identificar y manifestar sus emociones y sentimientos, expresando las causas de los mismos mediante el lenguaje verbal. (D.EIB.10.3.) | M13: Identificarse como miembro de una familia reconociéndose como parte importante de la misma. | N13: Practicar con autonomía hábitos de higiene personal como lavarse las manos, los dientes y la cara. | O13: Practicar hábitos de orden ubicando los objetos en el lugar correspondiente. | P13: Practicar las acciones a seguir en situaciones de riesgo como: temblores, incendios, entre otros, determinadas en el plan de contingencia institucional. | Q13: Practicar normas de seguridad para evitar accidentes a los que se puede exponer en su entorno inmediato. | R13: Realiza independientemente normas de aseo al ir al baño. | S13: Reconocer la importancia del uso del casco y demás indumentaria de pro tección para protegerse de lesiones en actividades que requieran su uso | T13: Reconocer situaciones problémicas en las actividades escolares para solucionarlas de forma creativa y con autonomía. | U13: Seleccionar las prendas de vestir de acuerdo al estado climático (prendas para el frío / prendas para el calor). | V13: Tomar decisiones con respecto a la elección de actividades, vestuario entre otros, en función de sus gustos y preferencias, argumentando las mismas. | W13: Utilizar la cuchara, tenedor y el vaso cuando se alimenta de manera autónoma. | X13: Vestirse y desvestirse de manera independiente con prendas de vestir sencillas. (D.EIB.10.5) | Z13: Apoyar y motivar a otras personas a participar en actividades grupales, particularmente a quienes muestran dificultades al hacerlo | AA13: Asumir y respetar normas de convivencia en la institución de educación inicial y en el hogar acordadas con el adulto. (D.EIB.10.15.) | AB13: Colaborar en actividades que se desarrollan con otros niños y adultos de su entorno. | AC13: Demostrar actitudes de solidaridad ante situaciones de necesidad de sus compañeros y adultos de su entorno | AD13: Demostrar cortesía y respeto hacia los actores viales (peatones, conductores, motociclistas, ciclistas, personas con discapacidad, movilidad reducida, grupos vulnerables, pasajeros, agentes y policías de tránsito) a través de actividades lúdicas que promuevan comportamientos adecuados en situaciones de tránsito | AE13: Demostrar preferencia de jugar la mayor parte del tiempo con un amigo estableciendo niveles de empatías más estables. | AF13: Demostrar sensibilidad ante deseos, emociones y sentimientos de otras personas. | AG13: Desarrollar la capacidad de esperar para obtener una recompensa mayor en el futuro. | AH13: Identificar instituciones y profesiones que brindan servicios a la comunidad y los roles que ellos cumplen. | AI13: Identificar las profesiones, oficios y ocupaciones que cumplen los miembros de su familia. | AJ13: Incrementar su campo de interrelación con otras personas a más del grupo familiar y escolar interactuando con mayor facilidad. | AK13: Observar las expresiones faciales y comportamientos de otros niños y niñas en actividades lúdicas para identificar sus emociones, guiar sus propias acciones y fomentar un ambiente de convivencia armónica | AL13: Participar juegos grupales siguiendo las reglas y asumiendo roles que le permitan mantener un ambiente armónico con sus pares. (D.EIB.10.11.) | AM13: Practicar la costumbre de ahorrar para ocasiones y casos especiales | AN13: Respetar las diferencias individuales que existe entre sus compañeros como: género, diversidad cultural, necesidades especiales, estructura familiar, entre otros. | AP13: Comunicar de manera asertiva sus preferencias o desacuerdos al interactuar con sus pares reconociendo cómo sus expresiones o acciones influyen en las otras personas. | AQ13: Construir conexiones emocionales con su contexto natural (plantas, animales, agua, tierra, aire) y social. | AR13: dentificar en las actividades diarias oportunidades para aprovechar los recursos y reducir los residuos para proteger el entorno natural | AS13: Diferenciar entre alimentos nutritivos y no nutritivos identificando los beneficios de una alimentación sana y saludable. | AT13: Diferenciar entre lo que le pertenece, lo que pertenece a los demás y lo que pertenece al grupo o comunidad. | AU13: Diferenciar los seres vivos y elementos no vivos de su entorno explorando su mundo natural. | AV13: Establecer comparaciones entre los elementos del entorno a través de la discriminación sensorial. | AW13: Explorar e identificar los diferentes elementos y fenómenos del entorno natural mediante procesos que propicien la indagación. | AX13: Identificar características de las plantas por su utilidad, estableciendo diferencias entre ellas. | AY13: Identificar las características de los animales domésticos y silvestres estableciendo las diferencias entre ellos. | AZ13: Identificar las características del mar y reconocerlo como una parte integral del territorio nacional | BA13: Identificar prácticas socioculturales de su localidad demostrando curiosidad ante sus tradiciones. | BB13: Observar el proceso del ciclo vital de las plantas mediante actividades de experimentación. | BC13: Participar en actividades lúdicas para identificar prácticas de movilidad que ayudan a cuidar el planeta | BD13: Participar en algunas prácticas tradicionales de su entorno disfrutando y respetando las diferentes manifestaciones culturales | BE13: Practicar hábitos de cuidado y conservación del medio ambiente que eviten la contaminación del aire, suelo y agua. (D.EIB.10.19.) | BF13: Realizar acciones de cuidado y protección de plantas y animales de su entorno erradicando actitudes de maltrato. | BG13: Reconocer cómo las personas utilizan el dinero en su entorno familiar para satisfacer sus necesidades y deseos | BH13: Reconocer las consecuencias de no cuidar sus pertenencias. | BI13: Reconocer los medios de transporte sostenibles, como: bicicleta, scooters, patinetes, transporte público, tranvías, metros y, caminar; por medio de actividades lúdicas | BK13: Asociar las formas de los objetos del entorno con figuras geométricas bidimensionales | BL13: Clasificar objetos con dos atributos (tamaño, color o forma). | BM13: Comparar y armar colecciones de más, igual y menos objetos. | BN13: Comparar y ordenar secuencialmente un conjunto pequeño de objetos de acuerdo con su tamaño. | BO13: Comprender la relación de número-cantidad hasta el 10. | BP13: Comprender la relación del numeral (representación simbólica del número) con la cantidad hasta el 5. | BQ13: Contar oralmente del 1 al 15 con secuencia numérica. | BR13: Continuar y reproducir patrones simples con objetos concretos y representaciones gráficas. | BS13: Establecer la relación de correspondencia entre los elementos de colecciones de objetos. | BT13: Identificar características de mañana, tarde y noche | BU13: Identificar en los objetos las nociones de medida: largo/ corto, grueso/delgado. | BV13: Identificar figuras geométricas básicas: círculo, cuadrado y triángulo en objetos del entorno y en representaciones gráficas. | BW13: Identificar la diferencia entre lo que se desea y lo que se necesita | BX13: Identificar las nociones de tiempo en acciones que siceden antes, ahora y después | BY13: Identificar los números de emergencia a través de actividades lúdicas, y reconocer cuándo pedir ayuda en situaciones sencillas. | BZ13: Identificar semejanzas y diferencias en objetos del entorno con criterios de forma, color y tamaño | CA13: Ordenar en secuencias lógica sucesos de hasta cinco eventos en representaciones gráficas de sus actividades de la rutina diaria y en escenas de cuentos | CB13: Reconocer billetes y monedas en situaciones de la vida real | CC13: Reconocer la ubicación de objetos en relación a sí mismo y diferentes puntos de referencia según las nociones espaciales de: entre, adelante/atrás, junto a, cerca/lejos | CD13: Reconocer los colores secundarios en objetos e imágenes del entorno. | CE13: Reconocer y comparar características personales (estatura, edad, u atributos físicos) al establecer relaciones básicas de tamaño y cantidad en actividades escolares. | CF13: Relacionar las distintas formas de adquirir dinero con el trabajo y el esfuerzo. | CH13: Asociar la imagen de la portada con el título de los cuentos conocidos. | CI13: Colaborar en la creación de textos colectivos con la ayuda del docente. | CJ13: Comprender el derecho propio y de las otras personas a decir que no como una respuesta válida y respetable. | CK13: Comunicarse a través de dibujos de objetos con detalles que lo vuelven identificables, como representación simbólica de sus ideas. | CL13: Comunicarse incorporando palabras nuevas a su vocabulario en función de los ambientes y experiencias en las que interactúa. | CM13: Contar un cuento en base a sus imágenes a partir de la portada y siguiendo la secuencia de las páginas. | CN13: Describir oralmente imágenes gráficas (pictogramas) y digitales, estructurando oraciones más elaboradas que describan a los objetos que observa. | CO13: Describir oralmente imágenes relacionadas con los derechos de las personas en situación de movilidad | CP13: Expresarse oralmente pronunciando correctamente la mayoría de las palabras puede presentarse dificultades en la pronunciación de s, y la r. | CQ13: Expresarse utilizando oraciones cortas y completas manteniendo el orden de las palabras. | CR13: Identificar “auditivamente” el fonema (sonido) inicial de las palabras más utilizadas. | CS13: Identificar una persona adulta de confianza para solicitar apoyo al enfrentar desafíos emocionales en situaciones cotidianas del entorno escolar | CT13: Participar en conversaciones más complejas y largas manteniéndose dentro del tema. | CU13: Producir palabras que riman espontáneamente tomado en cuenta los sonidos finales de las mismas. | CV13: Realizar modificaciones del contenido de un cuento relatado por el adulto, cambiando partes del él como: acciones y final. | CW13: Realizar movimientos articulatorios complejos: movimientos de los labios juntos de izquierda a derecha, hacia adelante, movimiento de las mandíbulas a los lados, inflar las mejillas y movimiento de lengua de mayor dificultad | CX13: Reconocer etiquetas y rótulos de su entorno inmediato y los “lee”. | CY13: Relatar cuentos, narrados por el adulto, manteniendo la secuencia, sin la ayuda del paratexto. | CZ13: Reproducir trabalenguas sencillos, adivinanzas, canciones y poemas cortos, mejorando su pronunciación y potenciando su capacidad imaginativa. | DA13: Responder preguntas sobre un texto narrado por el adulto, relacionadas a los personajes y acciones principales. | DB13: Seguir instrucciones sencillas que involucren la ejecución de tres o más actividades | DD13: Cantar canciones siguiendo el ritmo y coordinando con las expresiones de su cuerpo. | DE13: Comunicar de manera escrita sus ideas intentando imitar letras o formas parecidas a letras. | DF13: Ejecutar patrones de más de dos ritmos con partes del cuerpo y elementos o instrumentos sonoros. | DG13: Expresar emociones utilizando materiales artísticos para reflejar su estado emocional para autocuidarse canalizando sentimientos de alegría, tristeza o frustración, sin asociar roles o conductas a expectativas de género | DH13: Expresar su opinión al observar una obra artística relacionada a la plástica o a la escultura. | DI13: Expresar sus vivencias y experiencias a través del dibujo libre. | DJ13: Mantener el ritmo y las secuencias de pasos sencillos durante la ejecución de coreografías. | DK13: Participar en dramatizaciones y actividades lúdicas que representen situaciones cotidianas en la vía para identificar y respetar las señales de tránsito básicas (como semáforos, señales de pare y cruces peatonales), promoviendo un comportamiento seguro y ordenado. | DL13: Participar en dramatizaciones, asumiendo roles de diferentes personas del entorno y de personajes de cuentos e historietas. | DM13: Participar en rondas populares, bailes y juegos tradicionales, asumiendo los roles y respetando las reglas. | DN13: Realizar actividades creativas utilizando las técnicas grafo plásticas con variedad de materiales. | DO13: PROMEDIO | DP13: Caminar y correr con soltura y seguridad manteniendo el equilibrio a diferentes distancias, orientaciones y ritmos en espacios parciales. | DQ13: Caminar, correr y saltar de un lugar a otro coordinadamente combinando estas formas de desplazamiento, a velocidades diferentes y en superficies planas e inclinadas con obstáculos. | DR13: Discriminar sonidos onomatopéyicos y diferencia los sonidos naturales de los artificiales | DS13: Ejecutar actividades coordinadamente y con un control adecuado de fuerza y tonicidad muscular como: lanzar, atrapar y patear objetos y pelotas. | DT13: Emplear su lado dominante en la realización de la mayoría de las actividades que utilice la mano, ojo y pie. | DU13: Galopar y salticar coordinadamente con obstáculos ejecutando circuitos. | DV13: Identificar en su cuerpo y en el de los demás partes y articulaciones del cuerpo humano, así como partes finas de la cara, a través de la exploración sensorial. | DW13: Mantener el equilibro al caminar sobre líneas rectas, curvas y quebradas con altura (aprox. 20 cm) logrando un adecuado control postural. | DX13: Mantener un adecuado control postural en diferentes posiciones del cuerpo y en desplazamientos. | DY13: Orientarse en el espacio realizando desplazamientos en función de consignas dadas con las nociones: entre, adelante-atrás, junto a, cerca-lejos | DZ13: Realiza varios movimientos y desplazamientos combinados a diferentes velocidades (rápido, lento), duración (largos y corto). | EA13: Realizar actividades de coordinación visomotriz con niveles de dificultad creciente en el tamaño y tipo de materiales. | EB13: Realizar desplazamientos y movimientos combinados utilizando el espacio total y parcial a diferentes distancias (largas-cortas) | EC13: Realizar ejercicios de equilibrio estático y dinámico, controlando los movimientos de las partes gruesas del cuerpo y estructurando motricidad facial y gestual según la consigna incrementando el lapso de tiempo. | ED13: Realizar ejercicios de simetría corporal como: identificar en el espejo y otros materiales las partes semejantes que conforman el lado derecho e izquierdo del cuerpo. | EE13: Realizar ejercicios que involucran movimientos segmentados de partes gruesas y finas del cuerpo (cuello, hombro, codo, muñeca, dedos, cadera, rodilla, tobillo, pie). | EF13: Realizar movimientos diferenciados con los lados laterales del cuerpo (un lado y otro lado). | EG13: Realizar movimientos para la coordinación de ojo y pie como: patear pelotas hacia un punto fijo determinado. | EH13: Realizar representaciones gráficas utilizando el dibujo con detalles que le dan intencionalidad y sentido para identificarlos | EI13: Reconocer la importancia del peatón y respetar su espacio en la vía mediante actividades lúdicas que fomenten el aprendizaje de normas de tránsito. | EJ13: Representar la figura humana utilizando el monigote e incorporando detalles según la interiorización de su imagen corporal. | EK13: Saltar de un pie a otro alternadamente, de manera autónoma. | EL13: Saltar en dos pies en sentido vertical obstáculos de 20 a 30 cm en altura y en sentido horizontal longitudes de aproximadamente 50 a 70 cm. | EM13: Subir y bajar escaleras alternando los pies. | EN13: Trepar y reptar a diferentes ritmos y en posiciones corporales diversas (cúbito ventral y cúbito dorsal). | EO13: Ubicar algunas partes de su cuerpo en función de las nociones de al lado, junto a, cerca-lejos. | EP13: Utilizar el espacio parcial e inicia con el uso del espacio total para realizar representaciones gráficas. | EQ13: Utilizar la pinza digital para coger lápices, marcadores, pinceles y diversos tipos de materiales. | ER13: PROMEDIO | ET13: AUTOCONOCIMIENTO | EU13: PENSAMIENO CRITICO | EV13: MANEJO DE PROBLEMAS | EW13: TOMA DE DECISIONES | EX13: TRABAJO EN EQUIPO | EY13: CONCIENCIA SOCIAL | EZ13: RELACIONES INTERPERSONALES | FA13: MANEJO DE CONFLICTOS | FB13: MANEJO DE EMOCIONES Y SENTIMIENTOS | FE13: COMPORTAMENTAL | FF13: HORAS JUSTIFICADAS | FG13: HORAS INJUSTIFICADAS | FH13: ATRASOS
XCT17: NUMAT | XCU17: NL | XCV17: APELLIDO | XCW17: CODFC | XCX17: CODMAT
B18: 1 | C18: =IF(NOTAS!E21>"",NOTAS!E21,"") -> ALARCON GARCIA LIAM KAEL | G18: 9 | H18: 10 | I18: 7 | J18: 7 | K18: 10 | L18: 10 | M18: 10 | N18: 10 | O18: 7 | P18: 10 | Q18: 10 | R18: 10 | S18: 8 | T18: 7 | U18: 10 | V18: 10 | W18: 10 | X18: 8 | Y18: =IFERROR(INT(FIXED(TRUNC(AVERAGE(G18:X18),2),0)),"") -> 9 | Z18: 7 | AA18: 7 | AB18: 7 | AC18: 7 | AD18: 7 | AE18: 7 | AF18: 7 | AG18: 7 | AH18: 7 | AI18: 7 | AJ18: 7 | AK18: 7 | AL18: 7 | AM18: 7 | AN18: 7 | AO18: =IFERROR(INT(FIXED(TRUNC(AVERAGE(Z18:AN18),2),0)),"") -> 7 | AP18: 7 | AQ18: 7 | AR18: 7 | AS18: 7 | AT18: 7 | AU18: 7 | AV18: 7 | AW18: 7 | AX18: 7 | AY18: 7 | AZ18: 7 | BA18: 7 | BB18: 7 | BC18: 7 | BD18: 7 | BE18: 7 | BF18: 7 | BG18: 7 | BH18: 7 | BI18: 7 | BJ18: =IFERROR(INT(FIXED(TRUNC(AVERAGE(AP18:BI18),2),0)),"") -> 7 | BK18: 7 | BL18: 8 | BM18: 8 | BN18: 8 | BO18: 8 | BP18: 8 | BQ18: 8 | BR18: 8 | BS18: 8 | BT18: 8 | BU18: 8 | BV18: 8 | BW18: 8 | BX18: 8 | BY18: 8 | BZ18: 8 | CA18: 8 | CB18: 8 | CC18: 8 | CD18: 8 | CE18: 8 | CF18: 8 | CG18: =IFERROR(INT(FIXED(TRUNC(AVERAGE(BK18:CF18),2),0)),"") -> 8 | CH18: 7 | CI18: 7 | CJ18: 7 | CK18: 7 | CL18: 7 | CM18: 7 | CN18: 7 | CO18: 7 | CP18: 7 | CQ18: 7 | CR18: 7 | CS18: 7 | CT18: 7 | CU18: 7 | CV18: 7 | CW18: 7 | CX18: 7 | CY18: 7 | CZ18: 7 | DA18: 7 | DB18: 7 | DC18: =IFERROR(INT(FIXED(TRUNC(AVERAGE(CH18:DB18),2),0)),"") -> 7 | DD18: 7 | DE18: 7 | DF18: 7 | DG18: 7 | DH18: 7 | DI18: 7 | DJ18: 7 | DK18: 7 | DL18: 7 | DM18: 7 | DN18: 7 | DO18: =IFERROR(INT(FIXED(TRUNC(AVERAGE(DD18:DN18),2),0)),"") -> 7 | DP18: 8 | DQ18: 8 | DR18: 8 | DS18: 8 | DT18: 8 | DU18: 8 | DV18: 8 | DW18: 8 | DX18: 8 | DY18: 8 | DZ18: 8 | EA18: 8 | EB18: 8 | EC18: 8 | ED18: 8 | EE18: 8 | EF18: 8 | EG18: 8 | EH18: 8 | EI18: 8 | EJ18: 8 | EK18: 8 | EL18: 8 | EM18: 8 | EN18: 8 | EO18: 8 | EP18: 8 | EQ18: 8 | ER18: =IFERROR(INT(FIXED(TRUNC(AVERAGE(DP18:EQ18),2),0)),"") -> 8 | ES18: =IF(OR(Y18="",AO18="",BJ18="",CG18="",DC18="",DO18=""),"",IFERROR(AVERAGE(Y18,AO18,BJ18,CG18,DC18,DO18),"")) -> 7.5 | ET18: S | EU18: S | EV18: S | EW18: S | EX18: S | EY18: F | EZ18: S | FA18: F | FB18: S | FC18: =IF(OR(ET18="",EU18="",EV18="",EW18="",EX18="",EY18="",EZ18="",FA18="",FB18=""),"",IF(FD18>=35,"A+",IF(FD18>=33,"A-",IF(FD18>=30,"B+",IF(FD18>=27,"B-",IF(FD18>=20,"C+",IF(FD18>=18,"C-",IF(FD18>=15,"D+",IF(FD18>=13,"D-",IF(FD18>=11,"E+",IF(FD18>=0,"E-"))))))))))) -> A- | FD18: =IF(ET18="S",4,IF(ET18="F",3,IF(ET18="O",2,IF(ET18="N",1))))+IF(EU18="S",4,IF(EU18="F",3,IF(EU18="O",2,IF(EU18="N",1))))+IF(EV18="S",4,IF(EV18="F",3,IF(EV18="O",2,IF(EV18="N",1))))+IF(EW18="S",4,IF(EW18="F",3,IF(EW18="O",2,IF(EW18="N",1))))+IF(EX18="S",4,IF(EX18="F",3,IF(EX18="O",2,IF(EX18="N",1))))+IF(EY18="S",4,IF(EY18="F",3,IF(EY18="O",2,IF(EY18="N",1))))+IF(EZ18="S",4,IF(EZ18="F",3,IF(EZ18="O",2,IF(EZ18="N",1))))+IF(FA18="S",4,IF(FA18="F",3,IF(FA18="O",2,IF(FA18="N",1))))+IF(FB18="S",4,IF(FB18="F",3,IF(FB18="O",2,IF(FB18="N",1)))) -> 34 | FE18: =IF(FC18="","",FC18) -> A- | FF18: 15 | FH18: 0
B19: 2 | C19: =IF(NOTAS!E22>"",NOTAS!E22,"") -> BURGOS MARTINEZ ALEXANDER ABDIEL | G19: 9 | H19: 10 | I19: 7 | J19: 7 | K19: 8 | L19: 8 | M19: 10 | N19: 10 | O19: 7 | P19: 10 | Q19: 7 | R19: 10 | S19: 8 | T19: 7 | U19: 10 | V19: 10 | W19: 10 | X19: 10 | Y19: =IFERROR(INT(FIXED(TRUNC(AVERAGE(G19:X19),2),0)),"") -> 9 | Z19: 7 | AA19: 7 | AB19: 7 | AC19: 7 | AD19: 7 | AE19: 7 | AF19: 7 | AG19: 7 | AH19: 7 | AI19: 7 | AJ19: 7 | AK19: 7 | AL19: 7 | AM19: 7 | AN19: 7 | AO19: =IFERROR(INT(FIXED(TRUNC(AVERAGE(Z19:AN19),2),0)),"") -> 7 | AP19: 7 | AQ19: 7 | AR19: 7 | AS19: 7 | AT19: 7 | AU19: 7 | AV19: 7 | AW19: 7 | AX19: 7 | AY19: 7 | AZ19: 7 | BA19: 7 | BB19: 7 | BC19: 7 | BD19: 7 | BE19: 7 | BF19: 7 | BG19: 7 | BH19: 7 | BI19: 7 | BJ19: =IFERROR(INT(FIXED(TRUNC(AVERAGE(AP19:BI19),2),0)),"") -> 7 | BK19: 7 | BL19: 8 | BM19: 8 | BN19: 8 | BO19: 8 | BP19: 8 | BQ19: 8 | BR19: 8 | BS19: 8 | BT19: 8 | BU19: 8 | BV19: 8 | BW19: 8 | BX19: 8 | BY19: 8 | BZ19: 8 | CA19: 8 | CB19: 8 | CC19: 8 | CD19: 8 | CE19: 8 | CF19: 8 | CG19: =IFERROR(INT(FIXED(TRUNC(AVERAGE(BK19:CF19),2),0)),"") -> 8 | CH19: 7 | CI19: 7 | CJ19: 7 | CK19: 7 | CL19: 7 | CM19: 7 | CN19: 7 | CO19: 7 | CP19: 7 | CQ19: 7 | CR19: 7 | CS19: 7 | CT19: 7 | CU19: 7 | CV19: 7 | CW19: 7 | CX19: 7 | CY19: 7 | CZ19: 7 | DA19: 7 | DB19: 7 | DC19: =IFERROR(INT(FIXED(TRUNC(AVERAGE(CH19:DB19),2),0)),"") -> 7 | DD19: 7 | DE19: 7 | DF19: 7 | DG19: 7 | DH19: 7 | DI19: 7 | DJ19: 7 | DK19: 7 | DL19: 7 | DM19: 7 | DN19: 7 | DO19: =IFERROR(INT(FIXED(TRUNC(AVERAGE(DD19:DN19),2),0)),"") -> 7 | DP19: 10 | DQ19: 10 | DR19: 10 | DS19: 10 | DT19: 10 | DU19: 10 | DV19: 10 | DW19: 10 | DX19: 10 | DY19: 10 | DZ19: 10 | EA19: 10 | EB19: 10 | EC19: 10 | ED19: 10 | EE19: 10 | EF19: 10 | EG19: 10 | EH19: 10 | EI19: 10 | EJ19: 10 | EK19: 10 | EL19: 10 | EM19: 10 | EN19: 10 | EO19: 10 | EP19: 10 | EQ19: 10 | ER19: =IFERROR(INT(FIXED(TRUNC(AVERAGE(DP19:EQ19),2),0)),"") -> 10 | ES19: =IF(OR(Y19="",AO19="",BJ19="",CG19="",DC19="",DO19=""),"",IFERROR(AVERAGE(Y19,AO19,BJ19,CG19,DC19,DO19),"")) -> 7.5 | ET19: S | EU19: S | EV19: S | EW19: S | EX19: S | EY19: F | EZ19: F | FA19: F | FB19: F | FC19: =IF(OR(ET19="",EU19="",EV19="",EW19="",EX19="",EY19="",EZ19="",FA19="",FB19=""),"",IF(FD19>=35,"A+",IF(FD19>=33,"A-",IF(FD19>=30,"B+",IF(FD19>=27,"B-",IF(FD19>=20,"C+",IF(FD19>=18,"C-",IF(FD19>=15,"D+",IF(FD19>=13,"D-",IF(FD19>=11,"E+",IF(FD19>=0,"E-"))))))))))) -> B+ | FD19: =IF(ET19="S",4,IF(ET19="F",3,IF(ET19="O",2,IF(ET19="N",1))))+IF(EU19="S",4,IF(EU19="F",3,IF(EU19="O",2,IF(EU19="N",1))))+IF(EV19="S",4,IF(EV19="F",3,IF(EV19="O",2,IF(EV19="N",1))))+IF(EW19="S",4,IF(EW19="F",3,IF(EW19="O",2,IF(EW19="N",1))))+IF(EX19="S",4,IF(EX19="F",3,IF(EX19="O",2,IF(EX19="N",1))))+IF(EY19="S",4,IF(EY19="F",3,IF(EY19="O",2,IF(EY19="N",1))))+IF(EZ19="S",4,IF(EZ19="F",3,IF(EZ19="O",2,IF(EZ19="N",1))))+IF(FA19="S",4,IF(FA19="F",3,IF(FA19="O",2,IF(FA19="N",1))))+IF(FB19="S",4,IF(FB19="F",3,IF(FB19="O",2,IF(FB19="N",1)))) -> 32 | FE19: =IF(FC19="","",FC19) -> B+ | FH19: 10
B20: 3 | C20: =IF(NOTAS!E23>"",NOTAS!E23,"") -> CARREÑO SANCHEZ AMMY VALENTINA | G20: 9 | H20: 10 | I20: 7 | J20: 10 | K20: 10 | L20: 10 | M20: 10 | N20: 10 | O20: 10 | P20: 10 | Q20: 10 | R20: 10 | S20: 8 | T20: 10 | U20: 10 | V20: 10 | W20: 10 | X20: 10 | Y20: =IFERROR(INT(FIXED(TRUNC(AVERAGE(G20:X20),2),0)),"") -> 10 | Z20: 10 | AA20: 10 | AB20: 10 | AC20: 10 | AD20: 10 | AE20: 10 | AF20: 10 | AG20: 10 | AH20: 8 | AI20: 8 | AJ20: 10 | AK20: 10 | AL20: 10 | AM20: 7 | AN20: 10 | AO20: =IFERROR(INT(FIXED(TRUNC(AVERAGE(Z20:AN20),2),0)),"") -> 10 | AP20: 10 | AQ20: 10 | AR20: 10 | AS20: 10 | AT20: 10 | AU20: 10 | AV20: 10 | AW20: 10 | AX20: 10 | AY20: 10 | AZ20: 10 | BA20: 10 | BB20: 10 | BC20: 10 | BD20: 10 | BE20: 10 | BF20: 10 | BG20: 10 | BH20: 10 | BI20: 10 | BJ20: =IFERROR(INT(FIXED(TRUNC(AVERAGE(AP20:BI20),2),0)),"") -> 10 | BK20: 10 | BL20: 10 | BM20: 10 | BN20: 10 | BO20: 1 | BP20: 10 | BQ20: 10 | BR20: 10 | BS20: 10 | BT20: 10 | BU20: 10 | BV20: 10 | BW20: 10 | BX20: 10 | BY20: 10 | BZ20: 10 | CA20: 10 | CB20: 10 | CC20: 10 | CD20: 10 | CE20: 10 | CF20: 10 | CG20: =IFERROR(INT(FIXED(TRUNC(AVERAGE(BK20:CF20),2),0)),"") -> 10 | CH20: 10 | CI20: 10 | CJ20: 10 | CK20: 10 | CL20: 10 | CM20: 10 | CN20: 10 | CO20: 10 | CP20: 10 | CQ20: 10 | CR20: 10 | CS20: 10 | CT20: 10 | CU20: 10 | CV20: 10 | CW20: 10 | CX20: 10 | CY20: 10 | CZ20: 10 | DA20: 10 | DB20: 10 | DC20: =IFERROR(INT(FIXED(TRUNC(AVERAGE(CH20:DB20),2),0)),"") -> 10 | DD20: 10 | DE20: 10 | DF20: 10 | DG20: 10 | DH20: 10 | DI20: 10 | DJ20: 10 | DK20: 10 | DL20: 10 | DM20: 10 | DN20: 10 | DO20: =IFERROR(INT(FIXED(TRUNC(AVERAGE(DD20:DN20),2),0)),"") -> 10 | DP20: 10 | DQ20: 10 | DR20: 10 | DS20: 10 | DT20: 10 | DU20: 10 | DV20: 10 | DW20: 10 | DX20: 10 | DY20: 10 | DZ20: 10 | EA20: 10 | EB20: 10 | EC20: 10 | ED20: 10 | EE20: 10 | EF20: 10 | EG20: 10 | EH20: 10 | EI20: 10 | EJ20: 10 | EK20: 10 | EL20: 10 | EM20: 10 | EN20: 10 | EO20: 10 | EP20: 10 | EQ20: 10 | ER20: =IFERROR(INT(FIXED(TRUNC(AVERAGE(DP20:EQ20),2),0)),"") -> 10 | ES20: =IF(OR(Y20="",AO20="",BJ20="",CG20="",DC20="",DO20=""),"",IFERROR(AVERAGE(Y20,AO20,BJ20,CG20,DC20,DO20),"")) -> 10 | ET20: S | EU20: S | EV20: S | EW20: S | EX20: S | EY20: S | EZ20: S | FA20: F | FB20: S | FC20: =IF(OR(ET20="",EU20="",EV20="",EW20="",EX20="",EY20="",EZ20="",FA20="",FB20=""),"",IF(FD20>=35,"A+",IF(FD20>=33,"A-",IF(FD20>=30,"B+",IF(FD20>=27,"B-",IF(FD20>=20,"C+",IF(FD20>=18,"C-",IF(FD20>=15,"D+",IF(FD20>=13,"D-",IF(FD20>=11,"E+",IF(FD20>=0,"E-"))))))))))) -> A+ | FD20: =IF(ET20="S",4,IF(ET20="F",3,IF(ET20="O",2,IF(ET20="N",1))))+IF(EU20="S",4,IF(EU20="F",3,IF(EU20="O",2,IF(EU20="N",1))))+IF(EV20="S",4,IF(EV20="F",3,IF(EV20="O",2,IF(EV20="N",1))))+IF(EW20="S",4,IF(EW20="F",3,IF(EW20="O",2,IF(EW20="N",1))))+IF(EX20="S",4,IF(EX20="F",3,IF(EX20="O",2,IF(EX20="N",1))))+IF(EY20="S",4,IF(EY20="F",3,IF(EY20="O",2,IF(EY20="N",1))))+IF(EZ20="S",4,IF(EZ20="F",3,IF(EZ20="O",2,IF(EZ20="N",1))))+IF(FA20="S",4,IF(FA20="F",3,IF(FA20="O",2,IF(FA20="N",1))))+IF(FB20="S",4,IF(FB20="F",3,IF(FB20="O",2,IF(FB20="N",1)))) -> 35 | FE20: =IF(FC20="","",FC20) -> A+ | FH20: 0
B21: 4 | C21: =IF(NOTAS!E24>"",NOTAS!E24,"") -> CASTRO GOMEZ ANNIA VALENTINA | G21: 9 | H21: 10 | I21: 7 | J21: 10 | K21: 10 | L21: 10 | M21: 10 | N21: 10 | O21: 10 | P21: 10 | Q21: 10 | R21: 10 | S21: 8 | T21: 10 | U21: 10 | V21: 10 | W21: 10 | X21: 10 | Y21: =IFERROR(INT(FIXED(TRUNC(AVERAGE(G21:X21),2),0)),"") -> 10 | Z21: 10 | AA21: 10 | AB21: 10 | AC21: 10 | AD21: 10 | AE21: 10 | AF21: 10 | AG21: 10 | AH21: 8 | AI21: 8 | AJ21: 10 | AK21: 10 | AL21: 10 | AM21: 7 | AN21: 10 | AO21: =IFERROR(INT(FIXED(TRUNC(AVERAGE(Z21:AN21),2),0)),"") -> 10 | AP21: 10 | AQ21: 10 | AR21: 10 | AS21: 10 | AT21: 10 | AU21: 10 | AV21: 10 | AW21: 10 | AX21: 10 | AY21: 10 | AZ21: 10 | BA21: 10 | BB21: 10 | BC21: 10 | BD21: 10 | BE21: 10 | BF21: 10 | BG21: 10 | BH21: 10 | BI21: 10 | BJ21: =IFERROR(INT(FIXED(TRUNC(AVERAGE(AP21:BI21),2),0)),"") -> 10 | BK21: 10 | BL21: 10 | BM21: 10 | BN21: 10 | BO21: 10 | BP21: 10 | BQ21: 10 | BR21: 10 | BS21: 10 | BT21: 10 | BU21: 10 | BV21: 10 | BW21: 10 | BX21: 10 | BY21: 10 | BZ21: 10 | CA21: 10 | CB21: 10 | CC21: 10 | CD21: 10 | CE21: 10 | CF21: 10 | CG21: =IFERROR(INT(FIXED(TRUNC(AVERAGE(BK21:CF21),2),0)),"") -> 10 | CH21: 10 | CI21: 10 | CJ21: 10 | CK21: 10 | CL21: 10 | CM21: 10 | CN21: 10 | CO21: 10 | CP21: 10 | CQ21: 10 | CR21: 10 | CS21: 10 | CT21: 10 | CU21: 10 | CV21: 10 | CW21: 10 | CX21: 10 | CY21: 10 | CZ21: 10 | DA21: 10 | DB21: 10 | DC21: =IFERROR(INT(FIXED(TRUNC(AVERAGE(CH21:DB21),2),0)),"") -> 10 | DD21: 10 | DE21: 10 | DF21: 10 | DG21: 10 | DH21: 10 | DI21: 10 | DJ21: 10 | DK21: 10 | DL21: 10 | DM21: 10 | DN21: 10 | DO21: =IFERROR(INT(FIXED(TRUNC(AVERAGE(DD21:DN21),2),0)),"") -> 10 | DP21: 10 | DQ21: 10 | DR21: 10 | DS21: 10 | DT21: 10 | DU21: 10 | DV21: 10 | DW21: 10 | DX21: 10 | DY21: 10 | DZ21: 10 | EA21: 10 | EB21: 10 | EC21: 10 | ED21: 10 | EE21: 10 | EF21: 10 | EG21: 10 | EH21: 10 | EI21: 10 | EJ21: 10 | EK21: 10 | EL21: 10 | EM21: 10 | EN21: 10 | EO21: 10 | EP21: 10 | EQ21: 10 | ER21: =IFERROR(INT(FIXED(TRUNC(AVERAGE(DP21:EQ21),2),0)),"") -> 10 | ES21: =IF(OR(Y21="",AO21="",BJ21="",CG21="",DC21="",DO21=""),"",IFERROR(AVERAGE(Y21,AO21,BJ21,CG21,DC21,DO21),"")) -> 10 | ET21: S | EU21: S | EV21: S | EW21: S | EX21: S | EY21: S | EZ21: S | FA21: F | FB21: F | FC21: =IF(OR(ET21="",EU21="",EV21="",EW21="",EX21="",EY21="",EZ21="",FA21="",FB21=""),"",IF(FD21>=35,"A+",IF(FD21>=33,"A-",IF(FD21>=30,"B+",IF(FD21>=27,"B-",IF(FD21>=20,"C+",IF(FD21>=18,"C-",IF(FD21>=15,"D+",IF(FD21>=13,"D-",IF(FD21>=11,"E+",IF(FD21>=0,"E-"))))))))))) -> A- | FD21: =IF(ET21="S",4,IF(ET21="F",3,IF(ET21="O",2,IF(ET21="N",1))))+IF(EU21="S",4,IF(EU21="F",3,IF(EU21="O",2,IF(EU21="N",1))))+IF(EV21="S",4,IF(EV21="F",3,IF(EV21="O",2,IF(EV21="N",1))))+IF(EW21="S",4,IF(EW21="F",3,IF(EW21="O",2,IF(EW21="N",1))))+IF(EX21="S",4,IF(EX21="F",3,IF(EX21="O",2,IF(EX21="N",1))))+IF(EY21="S",4,IF(EY21="F",3,IF(EY21="O",2,IF(EY21="N",1))))+IF(EZ21="S",4,IF(EZ21="F",3,IF(EZ21="O",2,IF(EZ21="N",1))))+IF(FA21="S",4,IF(FA21="F",3,IF(FA21="O",2,IF(FA21="N",1))))+IF(FB21="S",4,IF(FB21="F",3,IF(FB21="O",2,IF(FB21="N",1)))) -> 34 | FE21: =IF(FC21="","",FC21) -> A- | FH21: 0
B22: 5 | C22: =IF(NOTAS!E25>"",NOTAS!E25,"") -> CEDEÑO AGUIRRE KEYLOR DEMIR | G22: 9 | H22: 10 | I22: 7 | J22: 10 | K22: 10 | L22: 10 | M22: 10 | N22: 10 | O22: 10 | P22: 10 | Q22: 10 | R22: 10 | S22: 8 | T22: 10 | U22: 10 | V22: 10 | W22: 10 | X22: 10 | Y22: =IFERROR(INT(FIXED(TRUNC(AVERAGE(G22:X22),2),0)),"") -> 10 | Z22: 10 | AA22: 10 | AB22: 10 | AC22: 10 | AD22: 10 | AE22: 10 | AF22: 10 | AG22: 10 | AH22: 8 | AI22: 8 | AJ22: 10 | AK22: 10 | AL22: 10 | AM22: 7 | AN22: 10 | AO22: =IFERROR(INT(FIXED(TRUNC(AVERAGE(Z22:AN22),2),0)),"") -> 10 | AP22: 10 | AQ22: 10 | AR22: 10 | AS22: 10 | AT22: 10 | AU22: 10 | AV22: 10 | AW22: 10 | AX22: 10 | AY22: 10 | AZ22: 10 | BA22: 10 | BB22: 10 | BC22: 10 | BD22: 10 | BE22: 10 | BF22: 10 | BG22: 10 | BH22: 10 | BI22: 10 | BJ22: =IFERROR(INT(FIXED(TRUNC(AVERAGE(AP22:BI22),2),0)),"") -> 10 | BK22: 10 | BL22: 10 | BM22: 10 | BN22: 10 | BO22: 10 | BP22: 10 | BQ22: 10 | BR22: 10 | BS22: 10 | BT22: 10 | BU22: 10 | BV22: 10 | BW22: 10 | BX22: 10 | BY22: 10 | BZ22: 10 | CA22: 10 | CB22: 10 | CC22: 10 | CD22: 10 | CE22: 10 | CF22: 10 | CG22: =IFERROR(INT(FIXED(TRUNC(AVERAGE(BK22:CF22),2),0)),"") -> 10 | CH22: 7 | CI22: 7 | CJ22: 7 | CK22: 7 | CL22: 7 | CM22: 7 | CN22: 7 | CO22: 7 | CP22: 7 | CQ22: 7 | CR22: 7 | CS22: 7 | CT22: 7 | CU22: 7 | CV22: 7 | CW22: 7 | CX22: 7 | CY22: 7 | CZ22: 7 | DA22: 7 | DB22: 7 | DC22: =IFERROR(INT(FIXED(TRUNC(AVERAGE(CH22:DB22),2),0)),"") -> 7 | DD22: 10 | DE22: 10 | DF22: 10 | DG22: 10 | DH22: 10 | DI22: 10 | DJ22: 10 | DK22: 10 | DL22: 10 | DM22: 10 | DN22: 10 | DO22: =IFERROR(INT(FIXED(TRUNC(AVERAGE(DD22:DN22),2),0)),"") -> 10 | DP22: 10 | DQ22: 10 | DR22: 10 | DS22: 10 | DT22: 10 | DU22: 10 | DV22: 10 | DW22: 10 | DX22: 10 | DY22: 10 | DZ22: 10 | EA22: 10 | EB22: 10 | EC22: 10 | ED22: 10 | EE22: 10 | EF22: 10 | EG22: 10 | EH22: 10 | EI22: 10 | EJ22: 10 | EK22: 10 | EL22: 10 | EM22: 10 | EN22: 10 | EO22: 10 | EP22: 10 | EQ22: 10 | ER22: =IFERROR(INT(FIXED(TRUNC(AVERAGE(DP22:EQ22),2),0)),"") -> 10 | ES22: =IF(OR(Y22="",AO22="",BJ22="",CG22="",DC22="",DO22=""),"",IFERROR(AVERAGE(Y22,AO22,BJ22,CG22,DC22,DO22),"")) -> 9.5 | ET22: S | EU22: S | EV22: S | EW22: S | EX22: S | EY22: F | EZ22: S | FA22: F | FB22: S | FC22: =IF(OR(ET22="",EU22="",EV22="",EW22="",EX22="",EY22="",EZ22="",FA22="",FB22=""),"",IF(FD22>=35,"A+",IF(FD22>=33,"A-",IF(FD22>=30,"B+",IF(FD22>=27,"B-",IF(FD22>=20,"C+",IF(FD22>=18,"C-",IF(FD22>=15,"D+",IF(FD22>=13,"D-",IF(FD22>=11,"E+",IF(FD22>=0,"E-"))))))))))) -> A- | FD22: =IF(ET22="S",4,IF(ET22="F",3,IF(ET22="O",2,IF(ET22="N",1))))+IF(EU22="S",4,IF(EU22="F",3,IF(EU22="O",2,IF(EU22="N",1))))+IF(EV22="S",4,IF(EV22="F",3,IF(EV22="O",2,IF(EV22="N",1))))+IF(EW22="S",4,IF(EW22="F",3,IF(EW22="O",2,IF(EW22="N",1))))+IF(EX22="S",4,IF(EX22="F",3,IF(EX22="O",2,IF(EX22="N",1))))+IF(EY22="S",4,IF(EY22="F",3,IF(EY22="O",2,IF(EY22="N",1))))+IF(EZ22="S",4,IF(EZ22="F",3,IF(EZ22="O",2,IF(EZ22="N",1))))+IF(FA22="S",4,IF(FA22="F",3,IF(FA22="O",2,IF(FA22="N",1))))+IF(FB22="S",4,IF(FB22="F",3,IF(FB22="O",2,IF(FB22="N",1)))) -> 34 | FE22: =IF(FC22="","",FC22) -> A- | FF22: 3 | FH22: 0
B23: 6 | C23: =IF(NOTAS!E26>"",NOTAS!E26,"") -> CERDAN TORO MADISON YARELIS | G23: 9 | H23: 10 | I23: 7 | J23: 7 | K23: 8 | L23: 8 | M23: 10 | N23: 10 | O23: 7 | P23: 7 | Q23: 7 | R23: 10 | S23: 8 | T23: 7 | U23: 10 | V23: 10 | W23: 10 | X23: 10 | Y23: =IFERROR(INT(FIXED(TRUNC(AVERAGE(G23:X23),2),0)),"") -> 9 | Z23: 7 | AA23: 7 | AB23: 7 | AC23: 7 | AD23: 7 | AE23: 7 | AF23: 7 | AG23: 7 | AH23: 7 | AI23: 7 | AJ23: 7 | AK23: 7 | AL23: 7 | AM23: 7 | AN23: 7 | AO23: =IFERROR(INT(FIXED(TRUNC(AVERAGE(Z23:AN23),2),0)),"") -> 7 | AP23: 7 | AQ23: 7 | AR23: 7 | AS23: 7 | AT23: 7 | AU23: 7 | AV23: 7 | AW23: 7 | AX23: 7 | AY23: 7 | AZ23: 7 | BA23: 7 | BB23: 7 | BC23: 7 | BD23: 7 | BE23: 7 | BF23: 7 | BG23: 7 | BH23: 7 | BI23: 7 | BJ23: =IFERROR(INT(FIXED(TRUNC(AVERAGE(AP23:BI23),2),0)),"") -> 7 | BK23: 10 | BL23: 10 | BM23: 10 | BN23: 10 | BO23: 10 | BP23: 10 | BQ23: 10 | BR23: 10 | BS23: 10 | BT23: 10 | BU23: 10 | BV23: 10 | BW23: 10 | BX23: 10 | BY23: 10 | BZ23: 10 | CA23: 10 | CB23: 10 | CC23: 10 | CD23: 10 | CE23: 10 | CF23: 10 | CG23: =IFERROR(INT(FIXED(TRUNC(AVERAGE(BK23:CF23),2),0)),"") -> 10 | CH23: 10 | CI23: 10 | CJ23: 10 | CK23: 10 | CL23: 10 | CM23: 10 | CN23: 10 | CO23: 10 | CP23: 10 | CQ23: 10 | CR23: 10 | CS23: 10 | CT23: 10 | CU23: 10 | CV23: 10 | CW23: 10 | CX23: 10 | CY23: 10 | CZ23: 10 | DA23: 10 | DB23: 10 | DC23: =IFERROR(INT(FIXED(TRUNC(AVERAGE(CH23:DB23),2),0)),"") -> 10 | DD23: 10 | DE23: 10 | DF23: 10 | DG23: 10 | DH23: 10 | DI23: 10 | DJ23: 10 | DK23: 10 | DL23: 10 | DM23: 10 | DN23: 10 | DO23: =IFERROR(INT(FIXED(TRUNC(AVERAGE(DD23:DN23),2),0)),"") -> 10 | DP23: 10 | DQ23: 10 | DR23: 10 | DS23: 10 | DT23: 10 | DU23: 10 | DV23: 10 | DW23: 10 | DX23: 10 | DY23: 10 | DZ23: 10 | EA23: 10 | EB23: 10 | EC23: 10 | ED23: 10 | EE23: 10 | EF23: 10 | EG23: 10 | EH23: 10 | EI23: 10 | EJ23: 10 | EK23: 10 | EL23: 10 | EM23: 10 | EN23: 10 | EO23: 10 | EP23: 10 | EQ23: 10 | ER23: =IFERROR(INT(FIXED(TRUNC(AVERAGE(DP23:EQ23),2),0)),"") -> 10 | ES23: =IF(OR(Y23="",AO23="",BJ23="",CG23="",DC23="",DO23=""),"",IFERROR(AVERAGE(Y23,AO23,BJ23,CG23,DC23,DO23),"")) -> 8.8333333 | ET23: S | EU23: S | EV23: S | EW23: S | EX23: S | EY23: F | EZ23: F | FA23: F | FB23: F | FC23: =IF(OR(ET23="",EU23="",EV23="",EW23="",EX23="",EY23="",EZ23="",FA23="",FB23=""),"",IF(FD23>=35,"A+",IF(FD23>=33,"A-",IF(FD23>=30,"B+",IF(FD23>=27,"B-",IF(FD23>=20,"C+",IF(FD23>=18,"C-",IF(FD23>=15,"D+",IF(FD23>=13,"D-",IF(FD23>=11,"E+",IF(FD23>=0,"E-"))))))))))) -> B+ | FD23: =IF(ET23="S",4,IF(ET23="F",3,IF(ET23="O",2,IF(ET23="N",1))))+IF(EU23="S",4,IF(EU23="F",3,IF(EU23="O",2,IF(EU23="N",1))))+IF(EV23="S",4,IF(EV23="F",3,IF(EV23="O",2,IF(EV23="N",1))))+IF(EW23="S",4,IF(EW23="F",3,IF(EW23="O",2,IF(EW23="N",1))))+IF(EX23="S",4,IF(EX23="F",3,IF(EX23="O",2,IF(EX23="N",1))))+IF(EY23="S",4,IF(EY23="F",3,IF(EY23="O",2,IF(EY23="N",1))))+IF(EZ23="S",4,IF(EZ23="F",3,IF(EZ23="O",2,IF(EZ23="N",1))))+IF(FA23="S",4,IF(FA23="F",3,IF(FA23="O",2,IF(FA23="N",1))))+IF(FB23="S",4,IF(FB23="F",3,IF(FB23="O",2,IF(FB23="N",1)))) -> 32 | FE23: =IF(FC23="","",FC23) -> B+ | FH23: 0
B24: 7 | C24: =IF(NOTAS!E27>"",NOTAS!E27,"") -> CEVALLOS ZAMBRANO IAN SAHIR | Y24: =IFERROR(INT(FIXED(TRUNC(AVERAGE(G24:X24),2),0)),"") | AO24: =IFERROR(INT(FIXED(TRUNC(AVERAGE(Z24:AN24),2),0)),"") | BJ24: =IFERROR(INT(FIXED(TRUNC(AVERAGE(AP24:BI24),2),0)),"") | CG24: =IFERROR(INT(FIXED(TRUNC(AVERAGE(BK24:CF24),2),0)),"") | DC24: =IFERROR(INT(FIXED(TRUNC(AVERAGE(CH24:DB24),2),0)),"") | DO24: =IFERROR(INT(FIXED(TRUNC(AVERAGE(DD24:DN24),2),0)),"") | ER24: =IFERROR(INT(FIXED(TRUNC(AVERAGE(DP24:EQ24),2),0)),"") | ES24: =IF(OR(Y24="",AO24="",BJ24="",CG24="",DC24="",DO24=""),"",IFERROR(AVERAGE(Y24,AO24,BJ24,CG24,DC24,DO24),"")) | FC24: =IF(OR(ET24="",EU24="",EV24="",EW24="",EX24="",EY24="",EZ24="",FA24="",FB24=""),"",IF(FD24>=35,"A+",IF(FD24>=33,"A-",IF(FD24>=30,"B+",IF(FD24>=27,"B-",IF(FD24>=20,"C+",IF(FD24>=18,"C-",IF(FD24>=15,"D+",IF(FD24>=13,"D-",IF(FD24>=11,"E+",IF(FD24>=0,"E-"))))))))))) | FD24: =IF(ET24="S",4,IF(ET24="F",3,IF(ET24="O",2,IF(ET24="N",1))))+IF(EU24="S",4,IF(EU24="F",3,IF(EU24="O",2,IF(EU24="N",1))))+IF(EV24="S",4,IF(EV24="F",3,IF(EV24="O",2,IF(EV24="N",1))))+IF(EW24="S",4,IF(EW24="F",3,IF(EW24="O",2,IF(EW24="N",1))))+IF(EX24="S",4,IF(EX24="F",3,IF(EX24="O",2,IF(EX24="N",1))))+IF(EY24="S",4,IF(EY24="F",3,IF(EY24="O",2,IF(EY24="N",1))))+IF(EZ24="S",4,IF(EZ24="F",3,IF(EZ24="O",2,IF(EZ24="N",1))))+IF(FA24="S",4,IF(FA24="F",3,IF(FA24="O",2,IF(FA24="N",1))))+IF(FB24="S",4,IF(FB24="F",3,IF(FB24="O",2,IF(FB24="N",1)))) -> 0 | FE24: =IF(FC24="","",FC24)
B25: 8 | C25: =IF(NOTAS!E28>"",NOTAS!E28,"") -> CONGACHA OÑA JEAN PIERRE | G25: 9 | H25: 10 | I25: 7 | J25: 10 | K25: 8 | L25: 10 | M25: 10 | N25: 10 | O25: 10 | P25: 10 | Q25: 10 | R25: 10 | S25: 8 | T25: 10 | U25: 10 | V25: 10 | W25: 10 | X25: 10 | Y25: =IFERROR(INT(FIXED(TRUNC(AVERAGE(G25:X25),2),0)),"") -> 10 | Z25: 10 | AA25: 10 | AB25: 10 | AC25: 10 | AD25: 10 | AE25: 10 | AF25: 10 | AG25: 10 | AH25: 8 | AI25: 8 | AJ25: 10 | AK25: 10 | AL25: 10 | AM25: 7 | AN25: 10 | AO25: =IFERROR(INT(FIXED(TRUNC(AVERAGE(Z25:AN25),2),0)),"") -> 10 | AP25: 10 | AQ25: 10 | AR25: 10 | AS25: 10 | AT25: 10 | AU25: 10 | AV25: 10 | AW25: 10 | AX25: 10 | AY25: 10 | AZ25: 10 | BA25: 10 | BB25: 10 | BC25: 10 | BD25: 10 | BE25: 10 | BF25: 10 | BG25: 10 | BH25: 10 | BI25: 10 | BJ25: =IFERROR(INT(FIXED(TRUNC(AVERAGE(AP25:BI25),2),0)),"") -> 10 | BK25: 10 | BL25: 10 | BM25: 10 | BN25: 10 | BO25: 10 | BP25: 10 | BQ25: 10 | BR25: 10 | BS25: 10 | BT25: 10 | BU25: 10 | BV25: 10 | BW25: 10 | BX25: 10 | BY25: 10 | BZ25: 10 | CA25: 10 | CB25: 10 | CC25: 10 | CD25: 10 | CE25: 10 | CF25: 10 | CG25: =IFERROR(INT(FIXED(TRUNC(AVERAGE(BK25:CF25),2),0)),"") -> 10 | CH25: 10 | CI25: 10 | CJ25: 10 | CK25: 10 | CL25: 10 | CM25: 10 | CN25: 10 | CO25: 10 | CP25: 10 | CQ25: 10 | CR25: 10 | CS25: 10 | CT25: 10 | CU25: 10 | CV25: 10 | CW25: 10 | CX25: 10 | CY25: 10 | CZ25: 10 | DA25: 10 | DB25: 10 | DC25: =IFERROR(INT(FIXED(TRUNC(AVERAGE(CH25:DB25),2),0)),"") -> 10 | DD25: 10 | DE25: 10 | DF25: 10 | DG25: 10 | DH25: 10 | DI25: 10 | DJ25: 10 | DK25: 10 | DL25: 10 | DM25: 10 | DN25: 10 | DO25: =IFERROR(INT(FIXED(TRUNC(AVERAGE(DD25:DN25),2),0)),"") -> 10 | DP25: 10 | DQ25: 10 | DR25: 10 | DS25: 10 | DT25: 10 | DU25: 10 | DV25: 10 | DW25: 10 | DX25: 10 | DY25: 10 | DZ25: 10 | EA25: 10 | EB25: 10 | EC25: 10 | ED25: 10 | EE25: 10 | EF25: 10 | EG25: 10 | EH25: 10 | EI25: 10 | EJ25: 10 | EK25: 10 | EL25: 10 | EM25: 10 | EN25: 10 | EO25: 10 | EP25: 10 | EQ25: 10 | ER25: =IFERROR(INT(FIXED(TRUNC(AVERAGE(DP25:EQ25),2),0)),"") -> 10 | ES25: =IF(OR(Y25="",AO25="",BJ25="",CG25="",DC25="",DO25=""),"",IFERROR(AVERAGE(Y25,AO25,BJ25,CG25,DC25,DO25),"")) -> 10 | ET25: S | EU25: S | EV25: S | EW25: S | EX25: S | EY25: S | EZ25: S | FA25: F | FB25: F | FC25: =IF(OR(ET25="",EU25="",EV25="",EW25="",EX25="",EY25="",EZ25="",FA25="",FB25=""),"",IF(FD25>=35,"A+",IF(FD25>=33,"A-",IF(FD25>=30,"B+",IF(FD25>=27,"B-",IF(FD25>=20,"C+",IF(FD25>=18,"C-",IF(FD25>=15,"D+",IF(FD25>=13,"D-",IF(FD25>=11,"E+",IF(FD25>=0,"E-"))))))))))) -> A- | FD25: =IF(ET25="S",4,IF(ET25="F",3,IF(ET25="O",2,IF(ET25="N",1))))+IF(EU25="S",4,IF(EU25="F",3,IF(EU25="O",2,IF(EU25="N",1))))+IF(EV25="S",4,IF(EV25="F",3,IF(EV25="O",2,IF(EV25="N",1))))+IF(EW25="S",4,IF(EW25="F",3,IF(EW25="O",2,IF(EW25="N",1))))+IF(EX25="S",4,IF(EX25="F",3,IF(EX25="O",2,IF(EX25="N",1))))+IF(EY25="S",4,IF(EY25="F",3,IF(EY25="O",2,IF(EY25="N",1))))+IF(EZ25="S",4,IF(EZ25="F",3,IF(EZ25="O",2,IF(EZ25="N",1))))+IF(FA25="S",4,IF(FA25="F",3,IF(FA25="O",2,IF(FA25="N",1))))+IF(FB25="S",4,IF(FB25="F",3,IF(FB25="O",2,IF(FB25="N",1)))) -> 34 | FE25: =IF(FC25="","",FC25) -> A- | FH25: 0
B26: 9 | C26: =IF(NOTAS!E29>"",NOTAS!E29,"") -> CUEVA VILLEGAS VALENTINA STEFANIA | G26: 9 | H26: 10 | I26: 7 | J26: 10 | K26: 10 | L26: 10 | M26: 10 | N26: 10 | O26: 10 | P26: 10 | Q26: 10 | R26: 10 | S26: 8 | T26: 7 | U26: 10 | V26: 10 | W26: 10 | X26: 10 | Y26: =IFERROR(INT(FIXED(TRUNC(AVERAGE(G26:X26),2),0)),"") -> 10 | Z26: 10 | AA26: 10 | AB26: 10 | AC26: 10 | AD26: 10 | AE26: 10 | AF26: 10 | AG26: 10 | AH26: 8 | AI26: 8 | AJ26: 10 | AK26: 10 | AL26: 10 | AM26: 7 | AN26: 10 | AO26: =IFERROR(INT(FIXED(TRUNC(AVERAGE(Z26:AN26),2),0)),"") -> 10 | AP26: 10 | AQ26: 10 | AR26: 10 | AS26: 10 | AT26: 10 | AU26: 10 | AV26: 10 | AW26: 10 | AX26: 10 | AY26: 10 | AZ26: 10 | BA26: 10 | BB26: 10 | BC26: 10 | BD26: 10 | BE26: 10 | BF26: 10 | BG26: 10 | BH26: 10 | BI26: 10 | BJ26: =IFERROR(INT(FIXED(TRUNC(AVERAGE(AP26:BI26),2),0)),"") -> 10 | BK26: 10 | BL26: 10 | BM26: 10 | BN26: 10 | BO26: 10 | BP26: 10 | BQ26: 10 | BR26: 10 | BS26: 10 | BT26: 10 | BU26: 10 | BV26: 10 | BW26: 10 | BX26: 10 | BY26: 10 | BZ26: 10 | CA26: 10 | CB26: 10 | CC26: 10 | CD26: 10 | CE26: 10 | CF26: 10 | CG26: =IFERROR(INT(FIXED(TRUNC(AVERAGE(BK26:CF26),2),0)),"") -> 10 | CH26: 10 | CI26: 10 | CJ26: 10 | CK26: 10 | CL26: 10 | CM26: 10 | CN26: 10 | CO26: 10 | CP26: 10 | CQ26: 10 | CR26: 10 | CS26: 10 | CT26: 10 | CU26: 10 | CV26: 10 | CW26: 10 | CX26: 10 | CY26: 10 | CZ26: 10 | DA26: 10 | DB26: 10 | DC26: =IFERROR(INT(FIXED(TRUNC(AVERAGE(CH26:DB26),2),0)),"") -> 10 | DD26: 10 | DE26: 10 | DF26: 10 | DG26: 10 | DH26: 10 | DI26: 10 | DJ26: 10 | DK26: 10 | DL26: 10 | DM26: 10 | DN26: 10 | DO26: =IFERROR(INT(FIXED(TRUNC(AVERAGE(DD26:DN26),2),0)),"") -> 10 | DP26: 10 | DQ26: 10 | DR26: 10 | DS26: 10 | DT26: 10 | DU26: 10 | DV26: 10 | DW26: 10 | DX26: 10 | DY26: 10 | DZ26: 10 | EA26: 10 | EB26: 10 | EC26: 10 | ED26: 10 | EE26: 10 | EF26: 10 | EG26: 10 | EH26: 10 | EI26: 10 | EJ26: 10 | EK26: 10 | EL26: 10 | EM26: 10 | EN26: 10 | EO26: 10 | EP26: 10 | EQ26: 10 | ER26: =IFERROR(INT(FIXED(TRUNC(AVERAGE(DP26:EQ26),2),0)),"") -> 10 | ES26: =IF(OR(Y26="",AO26="",BJ26="",CG26="",DC26="",DO26=""),"",IFERROR(AVERAGE(Y26,AO26,BJ26,CG26,DC26,DO26),"")) -> 10 | ET26: S | EU26: S | EV26: S | EW26: S | EX26: S | EY26: S | EZ26: S | FA26: S | FB26: S | FC26: =IF(OR(ET26="",EU26="",EV26="",EW26="",EX26="",EY26="",EZ26="",FA26="",FB26=""),"",IF(FD26>=35,"A+",IF(FD26>=33,"A-",IF(FD26>=30,"B+",IF(FD26>=27,"B-",IF(FD26>=20,"C+",IF(FD26>=18,"C-",IF(FD26>=15,"D+",IF(FD26>=13,"D-",IF(FD26>=11,"E+",IF(FD26>=0,"E-"))))))))))) -> A+ | FD26: =IF(ET26="S",4,IF(ET26="F",3,IF(ET26="O",2,IF(ET26="N",1))))+IF(EU26="S",4,IF(EU26="F",3,IF(EU26="O",2,IF(EU26="N",1))))+IF(EV26="S",4,IF(EV26="F",3,IF(EV26="O",2,IF(EV26="N",1))))+IF(EW26="S",4,IF(EW26="F",3,IF(EW26="O",2,IF(EW26="N",1))))+IF(EX26="S",4,IF(EX26="F",3,IF(EX26="O",2,IF(EX26="N",1))))+IF(EY26="S",4,IF(EY26="F",3,IF(EY26="O",2,IF(EY26="N",1))))+IF(EZ26="S",4,IF(EZ26="F",3,IF(EZ26="O",2,IF(EZ26="N",1))))+IF(FA26="S",4,IF(FA26="F",3,IF(FA26="O",2,IF(FA26="N",1))))+IF(FB26="S",4,IF(FB26="F",3,IF(FB26="O",2,IF(FB26="N",1)))) -> 36 | FE26: =IF(FC26="","",FC26) -> A+ | FH26: 0
B27: 10 | C27: =IF(NOTAS!E30>"",NOTAS!E30,"") -> DE LA CRUZ VALLEJO JOEL ALEXANDER | G27: 9 | H27: 10 | I27: 7 | J27: 10 | K27: 10 | L27: 10 | M27: 10 | N27: 10 | O27: 10 | P27: 10 | Q27: 10 | R27: 10 | S27: 8 | T27: 7 | U27: 10 | V27: 10 | W27: 10 | X27: 10 | Y27: =IFERROR(INT(FIXED(TRUNC(AVERAGE(G27:X27),2),0)),"") -> 10 | Z27: 10 | AA27: 10 | AB27: 10 | AC27: 10 | AD27: 10 | AE27: 10 | AF27: 10 | AG27: 10 | AH27: 8 | AI27: 8 | AJ27: 10 | AK27: 10 | AL27: 10 | AM27: 7 | AN27: 10 | AO27: =IFERROR(INT(FIXED(TRUNC(AVERAGE(Z27:AN27),2),0)),"") -> 10 | AP27: 10 | AQ27: 10 | AR27: 10 | AS27: 10 | AT27: 10 | AU27: 10 | AV27: 10 | AW27: 10 | AX27: 10 | AY27: 10 | AZ27: 10 | BA27: 10 | BB27: 10 | BC27: 10 | BD27: 10 | BE27: 10 | BF27: 10 | BG27: 10 | BH27: 10 | BI27: 10 | BJ27: =IFERROR(INT(FIXED(TRUNC(AVERAGE(AP27:BI27),2),0)),"") -> 10 | BK27: 10 | BL27: 10 | BM27: 10 | BN27: 10 | BO27: 10 | BP27: 10 | BQ27: 10 | BR27: 10 | BS27: 10 | BT27: 10 | BU27: 10 | BV27: 10 | BW27: 10 | BX27: 10 | BY27: 10 | BZ27: 10 | CA27: 10 | CB27: 10 | CC27: 10 | CD27: 10 | CE27: 10 | CF27: 10 | CG27: =IFERROR(INT(FIXED(TRUNC(AVERAGE(BK27:CF27),2),0)),"") -> 10 | CH27: 10 | CI27: 10 | CJ27: 10 | CK27: 10 | CL27: 10 | CM27: 10 | CN27: 10 | CO27: 10 | CP27: 10 | CQ27: 10 | CR27: 10 | CS27: 10 | CT27: 10 | CU27: 10 | CV27: 10 | CW27: 10 | CX27: 10 | CY27: 10 | CZ27: 10 | DA27: 10 | DB27: 10 | DC27: =IFERROR(INT(FIXED(TRUNC(AVERAGE(CH27:DB27),2),0)),"") -> 10 | DD27: 10 | DE27: 10 | DF27: 10 | DG27: 10 | DH27: 10 | DI27: 10 | DJ27: 10 | DK27: 10 | DL27: 10 | DM27: 10 | DN27: 10 | DO27: =IFERROR(INT(FIXED(TRUNC(AVERAGE(DD27:DN27),2),0)),"") -> 10 | DP27: 10 | DQ27: 10 | DR27: 10 | DS27: 10 | DT27: 10 | DU27: 10 | DV27: 10 | DW27: 10 | DX27: 10 | DY27: 10 | DZ27: 10 | EA27: 10 | EB27: 10 | EC27: 10 | ED27: 10 | EE27: 10 | EF27: 10 | EG27: 10 | EH27: 10 | EI27: 10 | EJ27: 10 | EK27: 10 | EL27: 10 | EM27: 10 | EN27: 10 | EO27: 10 | EP27: 10 | EQ27: 10 | ER27: =IFERROR(INT(FIXED(TRUNC(AVERAGE(DP27:EQ27),2),0)),"") -> 10 | ES27: =IF(OR(Y27="",AO27="",BJ27="",CG27="",DC27="",DO27=""),"",IFERROR(AVERAGE(Y27,AO27,BJ27,CG27,DC27,DO27),"")) -> 10 | ET27: S | EU27: S | EV27: S | EW27: S | EX27: S | EY27: S | EZ27: S | FA27: S | FB27: S | FC27: =IF(OR(ET27="",EU27="",EV27="",EW27="",EX27="",EY27="",EZ27="",FA27="",FB27=""),"",IF(FD27>=35,"A+",IF(FD27>=33,"A-",IF(FD27>=30,"B+",IF(FD27>=27,"B-",IF(FD27>=20,"C+",IF(FD27>=18,"C-",IF(FD27>=15,"D+",IF(FD27>=13,"D-",IF(FD27>=11,"E+",IF(FD27>=0,"E-"))))))))))) -> A+ | FD27: =IF(ET27="S",4,IF(ET27="F",3,IF(ET27="O",2,IF(ET27="N",1))))+IF(EU27="S",4,IF(EU27="F",3,IF(EU27="O",2,IF(EU27="N",1))))+IF(EV27="S",4,IF(EV27="F",3,IF(EV27="O",2,IF(EV27="N",1))))+IF(EW27="S",4,IF(EW27="F",3,IF(EW27="O",2,IF(EW27="N",1))))+IF(EX27="S",4,IF(EX27="F",3,IF(EX27="O",2,IF(EX27="N",1))))+IF(EY27="S",4,IF(EY27="F",3,IF(EY27="O",2,IF(EY27="N",1))))+IF(EZ27="S",4,IF(EZ27="F",3,IF(EZ27="O",2,IF(EZ27="N",1))))+IF(FA27="S",4,IF(FA27="F",3,IF(FA27="O",2,IF(FA27="N",1))))+IF(FB27="S",4,IF(FB27="F",3,IF(FB27="O",2,IF(FB27="N",1)))) -> 36 | FE27: =IF(FC27="","",FC27) -> A+ | FH27: 0
B28: 11 | C28: =IF(NOTAS!E31>"",NOTAS!E31,"") -> DUEÑAS CALDERON LEONIDAS NICOLAI | G28: 9 | H28: 10 | I28: 7 | J28: 8 | K28: 8 | L28: 10 | M28: 10 | N28: 10 | O28: 7 | P28: 7 | Q28: 7 | R28: 10 | S28: 8 | T28: 7 | U28: 10 | V28: 10 | W28: 10 | X28: 10 | Y28: =IFERROR(INT(FIXED(TRUNC(AVERAGE(G28:X28),2),0)),"") -> 9 | Z28: 7 | AA28: 7 | AB28: 7 | AC28: 7 | AD28: 7 | AE28: 7 | AF28: 7 | AG28: 7 | AH28: 7 | AI28: 7 | AJ28: 7 | AK28: 7 | AL28: 7 | AM28: 7 | AN28: 7 | AO28: =IFERROR(INT(FIXED(TRUNC(AVERAGE(Z28:AN28),2),0)),"") -> 7 | AP28: 7 | AQ28: 7 | AR28: 7 | AS28: 7 | AT28: 7 | AU28: 7 | AV28: 7 | AW28: 7 | AX28: 7 | AY28: 7 | AZ28: 7 | BA28: 7 | BB28: 7 | BC28: 7 | BD28: 7 | BE28: 7 | BF28: 7 | BG28: 7 | BH28: 7 | BI28: 7 | BJ28: =IFERROR(INT(FIXED(TRUNC(AVERAGE(AP28:BI28),2),0)),"") -> 7 | BK28: 10 | BL28: 10 | BM28: 10 | BN28: 10 | BO28: 10 | BP28: 10 | BQ28: 10 | BR28: 10 | BS28: 10 | BT28: 10 | BU28: 10 | BV28: 10 | BW28: 10 | BX28: 10 | BY28: 10 | BZ28: 10 | CA28: 10 | CB28: 10 | CC28: 10 | CD28: 10 | CE28: 10 | CF28: 10 | CG28: =IFERROR(INT(FIXED(TRUNC(AVERAGE(BK28:CF28),2),0)),"") -> 10 | CH28: 10 | CI28: 10 | CJ28: 10 | CK28: 10 | CL28: 10 | CM28: 10 | CN28: 10 | CO28: 10 | CP28: 10 | CQ28: 10 | CR28: 10 | CS28: 10 | CT28: 10 | CU28: 10 | CV28: 10 | CW28: 10 | CX28: 10 | CY28: 10 | CZ28: 10 | DA28: 10 | DB28: 10 | DC28: =IFERROR(INT(FIXED(TRUNC(AVERAGE(CH28:DB28),2),0)),"") -> 10 | DD28: 10 | DE28: 10 | DF28: 10 | DG28: 10 | DH28: 10 | DI28: 10 | DJ28: 10 | DK28: 10 | DL28: 10 | DM28: 10 | DN28: 10 | DO28: =IFERROR(INT(FIXED(TRUNC(AVERAGE(DD28:DN28),2),0)),"") -> 10 | DP28: 10 | DQ28: 10 | DR28: 10 | DS28: 10 | DT28: 10 | DU28: 10 | DV28: 10 | DW28: 10 | DX28: 10 | DY28: 10 | DZ28: 10 | EA28: 10 | EB28: 10 | EC28: 10 | ED28: 10 | EE28: 10 | EF28: 10 | EG28: 10 | EH28: 10 | EI28: 10 | EJ28: 10 | EK28: 10 | EL28: 10 | EM28: 10 | EN28: 10 | EO28: 10 | EP28: 10 | EQ28: 10 | ER28: =IFERROR(INT(FIXED(TRUNC(AVERAGE(DP28:EQ28),2),0)),"") -> 10 | ES28: =IF(OR(Y28="",AO28="",BJ28="",CG28="",DC28="",DO28=""),"",IFERROR(AVERAGE(Y28,AO28,BJ28,CG28,DC28,DO28),"")) -> 8.8333333 | ET28: S | EU28: S | EV28: S | EW28: S | EX28: S | EY28: S | EZ28: F | FA28: F | FB28: F | FC28: =IF(OR(ET28="",EU28="",EV28="",EW28="",EX28="",EY28="",EZ28="",FA28="",FB28=""),"",IF(FD28>=35,"A+",IF(FD28>=33,"A-",IF(FD28>=30,"B+",IF(FD28>=27,"B-",IF(FD28>=20,"C+",IF(FD28>=18,"C-",IF(FD28>=15,"D+",IF(FD28>=13,"D-",IF(FD28>=11,"E+",IF(FD28>=0,"E-"))))))))))) -> A- | FD28: =IF(ET28="S",4,IF(ET28="F",3,IF(ET28="O",2,IF(ET28="N",1))))+IF(EU28="S",4,IF(EU28="F",3,IF(EU28="O",2,IF(EU28="N",1))))+IF(EV28="S",4,IF(EV28="F",3,IF(EV28="O",2,IF(EV28="N",1))))+IF(EW28="S",4,IF(EW28="F",3,IF(EW28="O",2,IF(EW28="N",1))))+IF(EX28="S",4,IF(EX28="F",3,IF(EX28="O",2,IF(EX28="N",1))))+IF(EY28="S",4,IF(EY28="F",3,IF(EY28="O",2,IF(EY28="N",1))))+IF(EZ28="S",4,IF(EZ28="F",3,IF(EZ28="O",2,IF(EZ28="N",1))))+IF(FA28="S",4,IF(FA28="F",3,IF(FA28="O",2,IF(FA28="N",1))))+IF(FB28="S",4,IF(FB28="F",3,IF(FB28="O",2,IF(FB28="N",1)))) -> 33 | FE28: =IF(FC28="","",FC28) -> A- | FH28: 5
B29: 12 | C29: =IF(NOTAS!E32>"",NOTAS!E32,"") -> GOMEZ CELI ELIAM LEVIT | G29: 9 | H29: 10 | I29: 7 | J29: 10 | K29: 8 | L29: 7 | M29: 10 | N29: 10 | O29: 10 | P29: 10 | Q29: 10 | R29: 10 | S29: 8 | T29: 10 | U29: 10 | V29: 10 | W29: 10 | X29: 10 | Y29: =IFERROR(INT(FIXED(TRUNC(AVERAGE(G29:X29),2),0)),"") -> 9 | Z29: 10 | AA29: 10 | AB29: 10 | AC29: 10 | AD29: 10 | AE29: 10 | AF29: 10 | AG29: 10 | AH29: 8 | AI29: 8 | AJ29: 10 | AK29: 10 | AL29: 10 | AM29: 7 | AN29: 10 | AO29: =IFERROR(INT(FIXED(TRUNC(AVERAGE(Z29:AN29),2),0)),"") -> 10 | AP29: 10 | AQ29: 10 | AR29: 10 | AS29: 10 | AT29: 10 | AU29: 10 | AV29: 10 | AW29: 10 | AX29: 10 | AY29: 10 | AZ29: 10 | BA29: 10 | BB29: 10 | BC29: 10 | BD29: 10 | BE29: 10 | BF29: 10 | BG29: 10 | BH29: 10 | BI29: 10 | BJ29: =IFERROR(INT(FIXED(TRUNC(AVERAGE(AP29:BI29),2),0)),"") -> 10 | BK29: 10 | BL29: 10 | BM29: 10 | BN29: 10 | BO29: 10 | BP29: 10 | BQ29: 10 | BR29: 10 | BS29: 10 | BT29: 10 | BU29: 10 | BV29: 10 | BW29: 10 | BX29: 10 | BY29: 10 | BZ29: 10 | CA29: 10 | CB29: 10 | CC29: 10 | CD29: 10 | CE29: 10 | CF29: 10 | CG29: =IFERROR(INT(FIXED(TRUNC(AVERAGE(BK29:CF29),2),0)),"") -> 10 | CH29: 10 | CI29: 10 | CJ29: 10 | CK29: 10 | CL29: 10 | CM29: 10 | CN29: 10 | CO29: 10 | CP29: 10 | CQ29: 10 | CR29: 10 | CS29: 10 | CT29: 10 | CU29: 10 | CV29: 10 | CW29: 10 | CX29: 10 | CY29: 10 | CZ29: 10 | DA29: 10 | DB29: 10 | DC29: =IFERROR(INT(FIXED(TRUNC(AVERAGE(CH29:DB29),2),0)),"") -> 10 | DD29: 8 | DE29: 8 | DF29: 8 | DG29: 8 | DH29: 8 | DI29: 8 | DJ29: 8 | DK29: 8 | DL29: 8 | DM29: 10 | DN29: 10 | DO29: =IFERROR(INT(FIXED(TRUNC(AVERAGE(DD29:DN29),2),0)),"") -> 8 | DP29: 10 | DQ29: 10 | DR29: 10 | DS29: 10 | DT29: 10 | DU29: 10 | DV29: 10 | DW29: 10 | DX29: 10 | DY29: 10 | DZ29: 10 | EA29: 10 | EB29: 10 | EC29: 10 | ED29: 10 | EE29: 10 | EF29: 10 | EG29: 10 | EH29: 10 | EI29: 10 | EJ29: 10 | EK29: 10 | EL29: 10 | EM29: 10 | EN29: 10 | EO29: 10 | EP29: 10 | EQ29: 10 | ER29: =IFERROR(INT(FIXED(TRUNC(AVERAGE(DP29:EQ29),2),0)),"") -> 10 | ES29: =IF(OR(Y29="",AO29="",BJ29="",CG29="",DC29="",DO29=""),"",IFERROR(AVERAGE(Y29,AO29,BJ29,CG29,DC29,DO29),"")) -> 9.5 | ET29: S | EU29: S | EV29: S | EW29: S | EX29: S | EY29: S | EZ29: S | FA29: F | FB29: F | FC29: =IF(OR(ET29="",EU29="",EV29="",EW29="",EX29="",EY29="",EZ29="",FA29="",FB29=""),"",IF(FD29>=35,"A+",IF(FD29>=33,"A-",IF(FD29>=30,"B+",IF(FD29>=27,"B-",IF(FD29>=20,"C+",IF(FD29>=18,"C-",IF(FD29>=15,"D+",IF(FD29>=13,"D-",IF(FD29>=11,"E+",IF(FD29>=0,"E-"))))))))))) -> A- | FD29: =IF(ET29="S",4,IF(ET29="F",3,IF(ET29="O",2,IF(ET29="N",1))))+IF(EU29="S",4,IF(EU29="F",3,IF(EU29="O",2,IF(EU29="N",1))))+IF(EV29="S",4,IF(EV29="F",3,IF(EV29="O",2,IF(EV29="N",1))))+IF(EW29="S",4,IF(EW29="F",3,IF(EW29="O",2,IF(EW29="N",1))))+IF(EX29="S",4,IF(EX29="F",3,IF(EX29="O",2,IF(EX29="N",1))))+IF(EY29="S",4,IF(EY29="F",3,IF(EY29="O",2,IF(EY29="N",1))))+IF(EZ29="S",4,IF(EZ29="F",3,IF(EZ29="O",2,IF(EZ29="N",1))))+IF(FA29="S",4,IF(FA29="F",3,IF(FA29="O",2,IF(FA29="N",1))))+IF(FB29="S",4,IF(FB29="F",3,IF(FB29="O",2,IF(FB29="N",1)))) -> 34 | FE29: =IF(FC29="","",FC29) -> A- | FH29: 0
B30: 13 | C30: =IF(NOTAS!E33>"",NOTAS!E33,"") -> GUILLEN ABRIL JEOVANNY EMMANUEL | G30: 9 | H30: 10 | I30: 7 | J30: 10 | K30: 10 | L30: 10 | M30: 10 | N30: 10 | O30: 10 | P30: 10 | Q30: 10 | R30: 10 | S30: 8 | T30: 10 | U30: 10 | V30: 10 | W30: 10 | X30: 10 | Y30: =IFERROR(INT(FIXED(TRUNC(AVERAGE(G30:X30),2),0)),"") -> 10 | Z30: 10 | AA30: 10 | AB30: 10 | AC30: 10 | AD30: 10 | AE30: 10 | AF30: 10 | AG30: 10 | AH30: 8 | AI30: 8 | AJ30: 10 | AK30: 10 | AL30: 10 | AM30: 10 | AN30: 10 | AO30: =IFERROR(INT(FIXED(TRUNC(AVERAGE(Z30:AN30),2),0)),"") -> 10 | AP30: 10 | AQ30: 10 | AR30: 10 | AS30: 10 | AT30: 10 | AU30: 10 | AV30: 10 | AW30: 10 | AX30: 10 | AY30: 10 | AZ30: 10 | BA30: 10 | BB30: 10 | BC30: 10 | BD30: 10 | BE30: 10 | BF30: 10 | BG30: 10 | BH30: 10 | BI30: 10 | BJ30: =IFERROR(INT(FIXED(TRUNC(AVERAGE(AP30:BI30),2),0)),"") -> 10 | BK30: 10 | BL30: 10 | BM30: 10 | BN30: 10 | BO30: 10 | BP30: 10 | BQ30: 10 | BR30: 10 | BS30: 10 | BT30: 10 | BU30: 10 | BV30: 10 | BW30: 10 | BX30: 10 | BY30: 10 | BZ30: 10 | CA30: 10 | CB30: 10 | CC30: 10 | CD30: 10 | CE30: 10 | CF30: 10 | CG30: =IFERROR(INT(FIXED(TRUNC(AVERAGE(BK30:CF30),2),0)),"") -> 10 | CH30: 10 | CI30: 10 | CJ30: 10 | CK30: 10 | CL30: 10 | CM30: 10 | CN30: 10 | CO30: 10 | CP30: 10 | CQ30: 10 | CR30: 10 | CS30: 10 | CT30: 10 | CU30: 10 | CV30: 10 | CW30: 10 | CX30: 10 | CY30: 10 | CZ30: 10 | DA30: 10 | DB30: 10 | DC30: =IFERROR(INT(FIXED(TRUNC(AVERAGE(CH30:DB30),2),0)),"") -> 10 | DD30: 10 | DE30: 10 | DF30: 10 | DG30: 10 | DH30: 10 | DI30: 10 | DJ30: 10 | DK30: 10 | DL30: 10 | DM30: 10 | DN30: 10 | DO30: =IFERROR(INT(FIXED(TRUNC(AVERAGE(DD30:DN30),2),0)),"") -> 10 | DP30: 10 | DQ30: 10 | DR30: 10 | DS30: 10 | DT30: 10 | DU30: 10 | DV30: 10 | DW30: 10 | DX30: 10 | DY30: 10 | DZ30: 10 | EA30: 10 | EB30: 10 | EC30: 10 | ED30: 10 | EE30: 10 | EF30: 10 | EG30: 10 | EH30: 10 | EI30: 10 | EJ30: 10 | EK30: 10 | EL30: 10 | EM30: 10 | EN30: 10 | EO30: 10 | EP30: 10 | EQ30: 10 | ER30: =IFERROR(INT(FIXED(TRUNC(AVERAGE(DP30:EQ30),2),0)),"") -> 10 | ES30: =IF(OR(Y30="",AO30="",BJ30="",CG30="",DC30="",DO30=""),"",IFERROR(AVERAGE(Y30,AO30,BJ30,CG30,DC30,DO30),"")) -> 10 | ET30: S | EU30: S | EV30: S | EW30: S | EX30: S | EY30: S | EZ30: S | FA30: S | FB30: F | FC30: =IF(OR(ET30="",EU30="",EV30="",EW30="",EX30="",EY30="",EZ30="",FA30="",FB30=""),"",IF(FD30>=35,"A+",IF(FD30>=33,"A-",IF(FD30>=30,"B+",IF(FD30>=27,"B-",IF(FD30>=20,"C+",IF(FD30>=18,"C-",IF(FD30>=15,"D+",IF(FD30>=13,"D-",IF(FD30>=11,"E+",IF(FD30>=0,"E-"))))))))))) -> A+ | FD30: =IF(ET30="S",4,IF(ET30="F",3,IF(ET30="O",2,IF(ET30="N",1))))+IF(EU30="S",4,IF(EU30="F",3,IF(EU30="O",2,IF(EU30="N",1))))+IF(EV30="S",4,IF(EV30="F",3,IF(EV30="O",2,IF(EV30="N",1))))+IF(EW30="S",4,IF(EW30="F",3,IF(EW30="O",2,IF(EW30="N",1))))+IF(EX30="S",4,IF(EX30="F",3,IF(EX30="O",2,IF(EX30="N",1))))+IF(EY30="S",4,IF(EY30="F",3,IF(EY30="O",2,IF(EY30="N",1))))+IF(EZ30="S",4,IF(EZ30="F",3,IF(EZ30="O",2,IF(EZ30="N",1))))+IF(FA30="S",4,IF(FA30="F",3,IF(FA30="O",2,IF(FA30="N",1))))+IF(FB30="S",4,IF(FB30="F",3,IF(FB30="O",2,IF(FB30="N",1)))) -> 35 | FE30: =IF(FC30="","",FC30) -> A+ | FH30: 0
B31: 14 | C31: =IF(NOTAS!E34>"",NOTAS!E34,"") -> LOOR ROLDAN HEYDAN YADIEL | G31: 7 | H31: 10 | I31: 7 | J31: 10 | K31: 8 | L31: 7 | M31: 10 | N31: 10 | O31: 7 | P31: 7 | Q31: 7 | R31: 10 | S31: 8 | T31: 7 | U31: 10 | V31: 7 | W31: 10 | X31: 10 | Y31: =IFERROR(INT(FIXED(TRUNC(AVERAGE(G31:X31),2),0)),"") -> 8 | Z31: 10 | AA31: 7 | AB31: 7 | AC31: 10 | AD31: 10 | AE31: 10 | AF31: 10 | AG31: 7 | AH31: 8 | AI31: 8 | AJ31: 10 | AK31: 7 | AL31: 10 | AM31: 7 | AN31: 8 | AO31: =IFERROR(INT(FIXED(TRUNC(AVERAGE(Z31:AN31),2),0)),"") -> 9 | AP31: 8 | AQ31: 8 | AR31: 8 | AS31: 8 | AT31: 8 | AU31: 8 | AV31: 8 | AW31: 8 | AX31: 8 | AY31: 8 | AZ31: 8 | BA31: 8 | BB31: 8 | BC31: 8 | BD31: 8 | BE31: 8 | BF31: 8 | BG31: 8 | BH31: 8 | BI31: 8 | BJ31: =IFERROR(INT(FIXED(TRUNC(AVERAGE(AP31:BI31),2),0)),"") -> 8 | BK31: 8 | BL31: 8 | BM31: 8 | BN31: 8 | BO31: 8 | BP31: 8 | BQ31: 8 | BR31: 8 | BS31: 8 | BT31: 8 | BU31: 8 | BV31: 8 | BW31: 8 | BX31: 8 | BY31: 8 | BZ31: 8 | CA31: 8 | CB31: 8 | CC31: 8 | CD31: 8 | CE31: 8 | CF31: 8 | CG31: =IFERROR(INT(FIXED(TRUNC(AVERAGE(BK31:CF31),2),0)),"") -> 8 | CH31: 7 | CI31: 7 | CJ31: 7 | CK31: 7 | CL31: 7 | CM31: 7 | CN31: 7 | CO31: 7 | CP31: 7 | CQ31: 7 | CR31: 7 | CS31: 7 | CT31: 7 | CU31: 7 | CV31: 7 | CW31: 7 | CX31: 7 | CY31: 7 | CZ31: 7 | DA31: 7 | DB31: 7 | DC31: =IFERROR(INT(FIXED(TRUNC(AVERAGE(CH31:DB31),2),0)),"") -> 7 | DD31: 7 | DE31: 7 | DF31: 10 | DG31: 10 | DH31: 10 | DI31: 10 | DJ31: 10 | DK31: 10 | DL31: 10 | DM31: 10 | DN31: 10 | DO31: =IFERROR(INT(FIXED(TRUNC(AVERAGE(DD31:DN31),2),0)),"") -> 9 | DP31: 8 | DQ31: 8 | DR31: 8 | DS31: 8 | DT31: 8 | DU31: 8 | DV31: 8 | DW31: 8 | DX31: 8 | DY31: 8 | DZ31: 8 | EA31: 8 | EB31: 8 | EC31: 8 | ED31: 8 | EE31: 8 | EF31: 8 | EG31: 8 | EH31: 8 | EI31: 8 | EJ31: 8 | EK31: 8 | EL31: 8 | EM31: 8 | EN31: 8 | EO31: 8 | EP31: 8 | EQ31: 8 | ER31: =IFERROR(INT(FIXED(TRUNC(AVERAGE(DP31:EQ31),2),0)),"") -> 8 | ES31: =IF(OR(Y31="",AO31="",BJ31="",CG31="",DC31="",DO31=""),"",IFERROR(AVERAGE(Y31,AO31,BJ31,CG31,DC31,DO31),"")) -> 8.1666667 | ET31: F | EU31: S | EV31: S | EW31: S | EX31: S | EY31: F | EZ31: S | FA31: F | FB31: F | FC31: =IF(OR(ET31="",EU31="",EV31="",EW31="",EX31="",EY31="",EZ31="",FA31="",FB31=""),"",IF(FD31>=35,"A+",IF(FD31>=33,"A-",IF(FD31>=30,"B+",IF(FD31>=27,"B-",IF(FD31>=20,"C+",IF(FD31>=18,"C-",IF(FD31>=15,"D+",IF(FD31>=13,"D-",IF(FD31>=11,"E+",IF(FD31>=0,"E-"))))))))))) -> B+ | FD31: =IF(ET31="S",4,IF(ET31="F",3,IF(ET31="O",2,IF(ET31="N",1))))+IF(EU31="S",4,IF(EU31="F",3,IF(EU31="O",2,IF(EU31="N",1))))+IF(EV31="S",4,IF(EV31="F",3,IF(EV31="O",2,IF(EV31="N",1))))+IF(EW31="S",4,IF(EW31="F",3,IF(EW31="O",2,IF(EW31="N",1))))+IF(EX31="S",4,IF(EX31="F",3,IF(EX31="O",2,IF(EX31="N",1))))+IF(EY31="S",4,IF(EY31="F",3,IF(EY31="O",2,IF(EY31="N",1))))+IF(EZ31="S",4,IF(EZ31="F",3,IF(EZ31="O",2,IF(EZ31="N",1))))+IF(FA31="S",4,IF(FA31="F",3,IF(FA31="O",2,IF(FA31="N",1))))+IF(FB31="S",4,IF(FB31="F",3,IF(FB31="O",2,IF(FB31="N",1)))) -> 32 | FE31: =IF(FC31="","",FC31) -> B+ | FH31: 0
